<robot name="pi_robot">

    <!-- * * * Link Definitions * * * -->

    <link name="base_link">
        <visual>
            <origin xyz="0 0 0.0" rpy="0 0 0"/>
            <geometry>
                <cylinder radius="0.1" length="0.1"/>
            </geometry>
            <material name="Cyan1">
                <color rgba="0 0.5 0.5 1.0"/>
            </material>
        </visual>
    </link>


    <link name="link_1">
        <visual>
            <origin xyz="0 0 0.5" rpy="0 0 0"/>
            <geometry>
                <cylinder radius="0.025" length="1"/>
            </geometry>
            <material name="Cyan1">
                <color rgba="0 0.9 0.9 1.0"/>
            </material>
        </visual>
    </link>

    <link name="link_2">
        <visual>
            <origin xyz="0 0.0 0.5" rpy="0 0 0"/>
            <geometry>
                <cylinder radius="0.025" length="1"/>
            </geometry>
            <material name="Black1">
                <color rgba="0.2 0.2 0.2 1.0"/>
            </material>
        </visual>
    </link>

    <link name="link_3">
        <visual>
            <origin xyz="0 0 0.5" rpy="0 0 0"/>
            <geometry>
                <cylinder radius="0.025" length="1"/>
            </geometry>
            <material name="Cyan2">
                <color rgba="0 0.7 0.7 1.0"/>
            </material>
        </visual>
    </link>


    <!-- * * * Joint Definitions * * * -->


    <joint name="base_joint" type="continuous">
        <parent link="base_link"/>
        <child link="link_1"/>
        <origin xyz="0 0 0" rpy="0 0 0"/>
        <axis xyz="0 0 1"/>
    </joint>

    <joint name="joint_1" type="continuous">
        <parent link="link_1"/>
        <child link="link_2"/>
        <origin xyz="0 0 1" rpy="0 0 0"/>
        <axis xyz="0 1 0"/>
    </joint>

    <joint name="joint_2" type="continuous">
        <parent link="link_2"/>
        <child link="link_3"/>
        <origin xyz="0 0 1" rpy="0 0 0"/>
        <axis xyz="0 1 0"/>
    </joint>

</robot>